{
 "cells": [
  {
   "cell_type": "code",
   "execution_count": 3,
   "id": "18e4cebc",
   "metadata": {},
   "outputs": [
    {
     "name": "stdout",
     "output_type": "stream",
     "text": [
      " * Serving Flask app '__main__'\n",
      " * Debug mode: off\n"
     ]
    },
    {
     "name": "stderr",
     "output_type": "stream",
     "text": [
      "Address already in use\n",
      "Port 8080 is in use by another program. Either identify and stop that program, or start the server with a different port.\n",
      "ERROR:root:Internal Python error in the inspect module.\n",
      "Below is the traceback from this internal error.\n",
      "\n"
     ]
    },
    {
     "name": "stdout",
     "output_type": "stream",
     "text": [
      "Traceback (most recent call last):\n",
      "  File \"/Users/yuhanzhang/opt/anaconda3/lib/python3.8/site-packages/werkzeug/serving.py\", line 911, in prepare_socket\n",
      "    s.bind(server_address)\n",
      "OSError: [Errno 48] Address already in use\n",
      "\n",
      "During handling of the above exception, another exception occurred:\n",
      "\n",
      "Traceback (most recent call last):\n",
      "  File \"/Users/yuhanzhang/opt/anaconda3/lib/python3.8/site-packages/IPython/core/interactiveshell.py\", line 3457, in run_code\n",
      "    exec(code_obj, self.user_global_ns, self.user_ns)\n",
      "  File \"/var/folders/vy/cfxbck9n24vf_56l8vyxt_sw0000gn/T/ipykernel_21363/1000082152.py\", line 57, in <module>\n",
      "    app.run(port=8080)\n",
      "  File \"/Users/yuhanzhang/opt/anaconda3/lib/python3.8/site-packages/flask/app.py\", line 1188, in run\n",
      "    run_simple(t.cast(str, host), port, self, **options)\n",
      "  File \"/Users/yuhanzhang/opt/anaconda3/lib/python3.8/site-packages/werkzeug/serving.py\", line 1062, in run_simple\n",
      "    s = prepare_socket(hostname, port)\n",
      "  File \"/Users/yuhanzhang/opt/anaconda3/lib/python3.8/site-packages/werkzeug/serving.py\", line 930, in prepare_socket\n",
      "    sys.exit(1)\n",
      "SystemExit: 1\n",
      "\n",
      "During handling of the above exception, another exception occurred:\n",
      "\n",
      "Traceback (most recent call last):\n",
      "  File \"/Users/yuhanzhang/opt/anaconda3/lib/python3.8/site-packages/IPython/core/ultratb.py\", line 1101, in get_records\n",
      "    return _fixed_getinnerframes(etb, number_of_lines_of_context, tb_offset)\n",
      "  File \"/Users/yuhanzhang/opt/anaconda3/lib/python3.8/site-packages/IPython/core/ultratb.py\", line 248, in wrapped\n",
      "    return f(*args, **kwargs)\n",
      "  File \"/Users/yuhanzhang/opt/anaconda3/lib/python3.8/site-packages/IPython/core/ultratb.py\", line 281, in _fixed_getinnerframes\n",
      "    records = fix_frame_records_filenames(inspect.getinnerframes(etb, context))\n",
      "  File \"/Users/yuhanzhang/opt/anaconda3/lib/python3.8/inspect.py\", line 1503, in getinnerframes\n",
      "    frameinfo = (tb.tb_frame,) + getframeinfo(tb, context)\n",
      "AttributeError: 'tuple' object has no attribute 'tb_frame'\n"
     ]
    },
    {
     "ename": "TypeError",
     "evalue": "object of type 'NoneType' has no len()",
     "output_type": "error",
     "traceback": [
      "\u001b[0;31m---------------------------------------------------------------------------\u001b[0m",
      "\u001b[0;31mOSError\u001b[0m                                   Traceback (most recent call last)",
      "\u001b[0;32m~/opt/anaconda3/lib/python3.8/site-packages/werkzeug/serving.py\u001b[0m in \u001b[0;36mprepare_socket\u001b[0;34m(hostname, port)\u001b[0m\n\u001b[1;32m    910\u001b[0m     \u001b[0;32mtry\u001b[0m\u001b[0;34m:\u001b[0m\u001b[0;34m\u001b[0m\u001b[0;34m\u001b[0m\u001b[0m\n\u001b[0;32m--> 911\u001b[0;31m         \u001b[0ms\u001b[0m\u001b[0;34m.\u001b[0m\u001b[0mbind\u001b[0m\u001b[0;34m(\u001b[0m\u001b[0mserver_address\u001b[0m\u001b[0;34m)\u001b[0m\u001b[0;34m\u001b[0m\u001b[0;34m\u001b[0m\u001b[0m\n\u001b[0m\u001b[1;32m    912\u001b[0m     \u001b[0;32mexcept\u001b[0m \u001b[0mOSError\u001b[0m \u001b[0;32mas\u001b[0m \u001b[0me\u001b[0m\u001b[0;34m:\u001b[0m\u001b[0;34m\u001b[0m\u001b[0;34m\u001b[0m\u001b[0m\n",
      "\u001b[0;31mOSError\u001b[0m: [Errno 48] Address already in use",
      "\nDuring handling of the above exception, another exception occurred:\n",
      "\u001b[0;31mSystemExit\u001b[0m                                Traceback (most recent call last)",
      "    \u001b[0;31m[... skipping hidden 1 frame]\u001b[0m\n",
      "\u001b[0;32m/var/folders/vy/cfxbck9n24vf_56l8vyxt_sw0000gn/T/ipykernel_21363/1000082152.py\u001b[0m in \u001b[0;36m<module>\u001b[0;34m\u001b[0m\n\u001b[1;32m     56\u001b[0m \u001b[0;32mif\u001b[0m \u001b[0m__name__\u001b[0m \u001b[0;34m==\u001b[0m \u001b[0;34m'__main__'\u001b[0m\u001b[0;34m:\u001b[0m\u001b[0;34m\u001b[0m\u001b[0;34m\u001b[0m\u001b[0m\n\u001b[0;32m---> 57\u001b[0;31m     \u001b[0mapp\u001b[0m\u001b[0;34m.\u001b[0m\u001b[0mrun\u001b[0m\u001b[0;34m(\u001b[0m\u001b[0mport\u001b[0m\u001b[0;34m=\u001b[0m\u001b[0;36m8080\u001b[0m\u001b[0;34m)\u001b[0m\u001b[0;34m\u001b[0m\u001b[0;34m\u001b[0m\u001b[0m\n\u001b[0m",
      "\u001b[0;32m~/opt/anaconda3/lib/python3.8/site-packages/flask/app.py\u001b[0m in \u001b[0;36mrun\u001b[0;34m(self, host, port, debug, load_dotenv, **options)\u001b[0m\n\u001b[1;32m   1187\u001b[0m         \u001b[0;32mtry\u001b[0m\u001b[0;34m:\u001b[0m\u001b[0;34m\u001b[0m\u001b[0;34m\u001b[0m\u001b[0m\n\u001b[0;32m-> 1188\u001b[0;31m             \u001b[0mrun_simple\u001b[0m\u001b[0;34m(\u001b[0m\u001b[0mt\u001b[0m\u001b[0;34m.\u001b[0m\u001b[0mcast\u001b[0m\u001b[0;34m(\u001b[0m\u001b[0mstr\u001b[0m\u001b[0;34m,\u001b[0m \u001b[0mhost\u001b[0m\u001b[0;34m)\u001b[0m\u001b[0;34m,\u001b[0m \u001b[0mport\u001b[0m\u001b[0;34m,\u001b[0m \u001b[0mself\u001b[0m\u001b[0;34m,\u001b[0m \u001b[0;34m**\u001b[0m\u001b[0moptions\u001b[0m\u001b[0;34m)\u001b[0m\u001b[0;34m\u001b[0m\u001b[0;34m\u001b[0m\u001b[0m\n\u001b[0m\u001b[1;32m   1189\u001b[0m         \u001b[0;32mfinally\u001b[0m\u001b[0;34m:\u001b[0m\u001b[0;34m\u001b[0m\u001b[0;34m\u001b[0m\u001b[0m\n",
      "\u001b[0;32m~/opt/anaconda3/lib/python3.8/site-packages/werkzeug/serving.py\u001b[0m in \u001b[0;36mrun_simple\u001b[0;34m(hostname, port, application, use_reloader, use_debugger, use_evalex, extra_files, exclude_patterns, reloader_interval, reloader_type, threaded, processes, request_handler, static_files, passthrough_errors, ssl_context)\u001b[0m\n\u001b[1;32m   1061\u001b[0m     \u001b[0;32mif\u001b[0m \u001b[0;32mnot\u001b[0m \u001b[0mis_running_from_reloader\u001b[0m\u001b[0;34m(\u001b[0m\u001b[0;34m)\u001b[0m\u001b[0;34m:\u001b[0m\u001b[0;34m\u001b[0m\u001b[0;34m\u001b[0m\u001b[0m\n\u001b[0;32m-> 1062\u001b[0;31m         \u001b[0ms\u001b[0m \u001b[0;34m=\u001b[0m \u001b[0mprepare_socket\u001b[0m\u001b[0;34m(\u001b[0m\u001b[0mhostname\u001b[0m\u001b[0;34m,\u001b[0m \u001b[0mport\u001b[0m\u001b[0;34m)\u001b[0m\u001b[0;34m\u001b[0m\u001b[0;34m\u001b[0m\u001b[0m\n\u001b[0m\u001b[1;32m   1063\u001b[0m         \u001b[0mfd\u001b[0m \u001b[0;34m=\u001b[0m \u001b[0ms\u001b[0m\u001b[0;34m.\u001b[0m\u001b[0mfileno\u001b[0m\u001b[0;34m(\u001b[0m\u001b[0;34m)\u001b[0m\u001b[0;34m\u001b[0m\u001b[0;34m\u001b[0m\u001b[0m\n",
      "\u001b[0;32m~/opt/anaconda3/lib/python3.8/site-packages/werkzeug/serving.py\u001b[0m in \u001b[0;36mprepare_socket\u001b[0;34m(hostname, port)\u001b[0m\n\u001b[1;32m    929\u001b[0m \u001b[0;34m\u001b[0m\u001b[0m\n\u001b[0;32m--> 930\u001b[0;31m         \u001b[0msys\u001b[0m\u001b[0;34m.\u001b[0m\u001b[0mexit\u001b[0m\u001b[0;34m(\u001b[0m\u001b[0;36m1\u001b[0m\u001b[0;34m)\u001b[0m\u001b[0;34m\u001b[0m\u001b[0;34m\u001b[0m\u001b[0m\n\u001b[0m\u001b[1;32m    931\u001b[0m \u001b[0;34m\u001b[0m\u001b[0m\n",
      "\u001b[0;31mSystemExit\u001b[0m: 1",
      "\nDuring handling of the above exception, another exception occurred:\n",
      "\u001b[0;31mTypeError\u001b[0m                                 Traceback (most recent call last)",
      "    \u001b[0;31m[... skipping hidden 1 frame]\u001b[0m\n",
      "\u001b[0;32m~/opt/anaconda3/lib/python3.8/site-packages/IPython/core/interactiveshell.py\u001b[0m in \u001b[0;36mshowtraceback\u001b[0;34m(self, exc_tuple, filename, tb_offset, exception_only, running_compiled_code)\u001b[0m\n\u001b[1;32m   2068\u001b[0m                     stb = ['An exception has occurred, use %tb to see '\n\u001b[1;32m   2069\u001b[0m                            'the full traceback.\\n']\n\u001b[0;32m-> 2070\u001b[0;31m                     stb.extend(self.InteractiveTB.get_exception_only(etype,\n\u001b[0m\u001b[1;32m   2071\u001b[0m                                                                      value))\n\u001b[1;32m   2072\u001b[0m                 \u001b[0;32melse\u001b[0m\u001b[0;34m:\u001b[0m\u001b[0;34m\u001b[0m\u001b[0;34m\u001b[0m\u001b[0m\n",
      "\u001b[0;32m~/opt/anaconda3/lib/python3.8/site-packages/IPython/core/ultratb.py\u001b[0m in \u001b[0;36mget_exception_only\u001b[0;34m(self, etype, value)\u001b[0m\n\u001b[1;32m    752\u001b[0m         \u001b[0mvalue\u001b[0m \u001b[0;34m:\u001b[0m \u001b[0mexception\u001b[0m \u001b[0mvalue\u001b[0m\u001b[0;34m\u001b[0m\u001b[0;34m\u001b[0m\u001b[0m\n\u001b[1;32m    753\u001b[0m         \"\"\"\n\u001b[0;32m--> 754\u001b[0;31m         \u001b[0;32mreturn\u001b[0m \u001b[0mListTB\u001b[0m\u001b[0;34m.\u001b[0m\u001b[0mstructured_traceback\u001b[0m\u001b[0;34m(\u001b[0m\u001b[0mself\u001b[0m\u001b[0;34m,\u001b[0m \u001b[0metype\u001b[0m\u001b[0;34m,\u001b[0m \u001b[0mvalue\u001b[0m\u001b[0;34m)\u001b[0m\u001b[0;34m\u001b[0m\u001b[0;34m\u001b[0m\u001b[0m\n\u001b[0m\u001b[1;32m    755\u001b[0m \u001b[0;34m\u001b[0m\u001b[0m\n\u001b[1;32m    756\u001b[0m     \u001b[0;32mdef\u001b[0m \u001b[0mshow_exception_only\u001b[0m\u001b[0;34m(\u001b[0m\u001b[0mself\u001b[0m\u001b[0;34m,\u001b[0m \u001b[0metype\u001b[0m\u001b[0;34m,\u001b[0m \u001b[0mevalue\u001b[0m\u001b[0;34m)\u001b[0m\u001b[0;34m:\u001b[0m\u001b[0;34m\u001b[0m\u001b[0;34m\u001b[0m\u001b[0m\n",
      "\u001b[0;32m~/opt/anaconda3/lib/python3.8/site-packages/IPython/core/ultratb.py\u001b[0m in \u001b[0;36mstructured_traceback\u001b[0;34m(self, etype, evalue, etb, tb_offset, context)\u001b[0m\n\u001b[1;32m    627\u001b[0m             \u001b[0mchained_exceptions_tb_offset\u001b[0m \u001b[0;34m=\u001b[0m \u001b[0;36m0\u001b[0m\u001b[0;34m\u001b[0m\u001b[0;34m\u001b[0m\u001b[0m\n\u001b[1;32m    628\u001b[0m             out_list = (\n\u001b[0;32m--> 629\u001b[0;31m                 self.structured_traceback(\n\u001b[0m\u001b[1;32m    630\u001b[0m                     \u001b[0metype\u001b[0m\u001b[0;34m,\u001b[0m \u001b[0mevalue\u001b[0m\u001b[0;34m,\u001b[0m \u001b[0;34m(\u001b[0m\u001b[0metb\u001b[0m\u001b[0;34m,\u001b[0m \u001b[0mchained_exc_ids\u001b[0m\u001b[0;34m)\u001b[0m\u001b[0;34m,\u001b[0m\u001b[0;34m\u001b[0m\u001b[0;34m\u001b[0m\u001b[0m\n\u001b[1;32m    631\u001b[0m                     chained_exceptions_tb_offset, context)\n",
      "\u001b[0;32m~/opt/anaconda3/lib/python3.8/site-packages/IPython/core/ultratb.py\u001b[0m in \u001b[0;36mstructured_traceback\u001b[0;34m(self, etype, value, tb, tb_offset, number_of_lines_of_context)\u001b[0m\n\u001b[1;32m   1365\u001b[0m         \u001b[0;32melse\u001b[0m\u001b[0;34m:\u001b[0m\u001b[0;34m\u001b[0m\u001b[0;34m\u001b[0m\u001b[0m\n\u001b[1;32m   1366\u001b[0m             \u001b[0mself\u001b[0m\u001b[0;34m.\u001b[0m\u001b[0mtb\u001b[0m \u001b[0;34m=\u001b[0m \u001b[0mtb\u001b[0m\u001b[0;34m\u001b[0m\u001b[0;34m\u001b[0m\u001b[0m\n\u001b[0;32m-> 1367\u001b[0;31m         return FormattedTB.structured_traceback(\n\u001b[0m\u001b[1;32m   1368\u001b[0m             self, etype, value, tb, tb_offset, number_of_lines_of_context)\n\u001b[1;32m   1369\u001b[0m \u001b[0;34m\u001b[0m\u001b[0m\n",
      "\u001b[0;32m~/opt/anaconda3/lib/python3.8/site-packages/IPython/core/ultratb.py\u001b[0m in \u001b[0;36mstructured_traceback\u001b[0;34m(self, etype, value, tb, tb_offset, number_of_lines_of_context)\u001b[0m\n\u001b[1;32m   1265\u001b[0m         \u001b[0;32mif\u001b[0m \u001b[0mmode\u001b[0m \u001b[0;32min\u001b[0m \u001b[0mself\u001b[0m\u001b[0;34m.\u001b[0m\u001b[0mverbose_modes\u001b[0m\u001b[0;34m:\u001b[0m\u001b[0;34m\u001b[0m\u001b[0;34m\u001b[0m\u001b[0m\n\u001b[1;32m   1266\u001b[0m             \u001b[0;31m# Verbose modes need a full traceback\u001b[0m\u001b[0;34m\u001b[0m\u001b[0;34m\u001b[0m\u001b[0;34m\u001b[0m\u001b[0m\n\u001b[0;32m-> 1267\u001b[0;31m             return VerboseTB.structured_traceback(\n\u001b[0m\u001b[1;32m   1268\u001b[0m                 \u001b[0mself\u001b[0m\u001b[0;34m,\u001b[0m \u001b[0metype\u001b[0m\u001b[0;34m,\u001b[0m \u001b[0mvalue\u001b[0m\u001b[0;34m,\u001b[0m \u001b[0mtb\u001b[0m\u001b[0;34m,\u001b[0m \u001b[0mtb_offset\u001b[0m\u001b[0;34m,\u001b[0m \u001b[0mnumber_of_lines_of_context\u001b[0m\u001b[0;34m\u001b[0m\u001b[0;34m\u001b[0m\u001b[0m\n\u001b[1;32m   1269\u001b[0m             )\n",
      "\u001b[0;32m~/opt/anaconda3/lib/python3.8/site-packages/IPython/core/ultratb.py\u001b[0m in \u001b[0;36mstructured_traceback\u001b[0;34m(self, etype, evalue, etb, tb_offset, number_of_lines_of_context)\u001b[0m\n\u001b[1;32m   1122\u001b[0m         \u001b[0;34m\"\"\"Return a nice text document describing the traceback.\"\"\"\u001b[0m\u001b[0;34m\u001b[0m\u001b[0;34m\u001b[0m\u001b[0m\n\u001b[1;32m   1123\u001b[0m \u001b[0;34m\u001b[0m\u001b[0m\n\u001b[0;32m-> 1124\u001b[0;31m         formatted_exception = self.format_exception_as_a_whole(etype, evalue, etb, number_of_lines_of_context,\n\u001b[0m\u001b[1;32m   1125\u001b[0m                                                                tb_offset)\n\u001b[1;32m   1126\u001b[0m \u001b[0;34m\u001b[0m\u001b[0m\n",
      "\u001b[0;32m~/opt/anaconda3/lib/python3.8/site-packages/IPython/core/ultratb.py\u001b[0m in \u001b[0;36mformat_exception_as_a_whole\u001b[0;34m(self, etype, evalue, etb, number_of_lines_of_context, tb_offset)\u001b[0m\n\u001b[1;32m   1080\u001b[0m \u001b[0;34m\u001b[0m\u001b[0m\n\u001b[1;32m   1081\u001b[0m \u001b[0;34m\u001b[0m\u001b[0m\n\u001b[0;32m-> 1082\u001b[0;31m         \u001b[0mlast_unique\u001b[0m\u001b[0;34m,\u001b[0m \u001b[0mrecursion_repeat\u001b[0m \u001b[0;34m=\u001b[0m \u001b[0mfind_recursion\u001b[0m\u001b[0;34m(\u001b[0m\u001b[0morig_etype\u001b[0m\u001b[0;34m,\u001b[0m \u001b[0mevalue\u001b[0m\u001b[0;34m,\u001b[0m \u001b[0mrecords\u001b[0m\u001b[0;34m)\u001b[0m\u001b[0;34m\u001b[0m\u001b[0;34m\u001b[0m\u001b[0m\n\u001b[0m\u001b[1;32m   1083\u001b[0m \u001b[0;34m\u001b[0m\u001b[0m\n\u001b[1;32m   1084\u001b[0m         \u001b[0mframes\u001b[0m \u001b[0;34m=\u001b[0m \u001b[0mself\u001b[0m\u001b[0;34m.\u001b[0m\u001b[0mformat_records\u001b[0m\u001b[0;34m(\u001b[0m\u001b[0mrecords\u001b[0m\u001b[0;34m,\u001b[0m \u001b[0mlast_unique\u001b[0m\u001b[0;34m,\u001b[0m \u001b[0mrecursion_repeat\u001b[0m\u001b[0;34m)\u001b[0m\u001b[0;34m\u001b[0m\u001b[0;34m\u001b[0m\u001b[0m\n",
      "\u001b[0;32m~/opt/anaconda3/lib/python3.8/site-packages/IPython/core/ultratb.py\u001b[0m in \u001b[0;36mfind_recursion\u001b[0;34m(etype, value, records)\u001b[0m\n\u001b[1;32m    380\u001b[0m     \u001b[0;31m# first frame (from in to out) that looks different.\u001b[0m\u001b[0;34m\u001b[0m\u001b[0;34m\u001b[0m\u001b[0;34m\u001b[0m\u001b[0m\n\u001b[1;32m    381\u001b[0m     \u001b[0;32mif\u001b[0m \u001b[0;32mnot\u001b[0m \u001b[0mis_recursion_error\u001b[0m\u001b[0;34m(\u001b[0m\u001b[0metype\u001b[0m\u001b[0;34m,\u001b[0m \u001b[0mvalue\u001b[0m\u001b[0;34m,\u001b[0m \u001b[0mrecords\u001b[0m\u001b[0;34m)\u001b[0m\u001b[0;34m:\u001b[0m\u001b[0;34m\u001b[0m\u001b[0;34m\u001b[0m\u001b[0m\n\u001b[0;32m--> 382\u001b[0;31m         \u001b[0;32mreturn\u001b[0m \u001b[0mlen\u001b[0m\u001b[0;34m(\u001b[0m\u001b[0mrecords\u001b[0m\u001b[0;34m)\u001b[0m\u001b[0;34m,\u001b[0m \u001b[0;36m0\u001b[0m\u001b[0;34m\u001b[0m\u001b[0;34m\u001b[0m\u001b[0m\n\u001b[0m\u001b[1;32m    383\u001b[0m \u001b[0;34m\u001b[0m\u001b[0m\n\u001b[1;32m    384\u001b[0m     \u001b[0;31m# Select filename, lineno, func_name to track frames with\u001b[0m\u001b[0;34m\u001b[0m\u001b[0;34m\u001b[0m\u001b[0;34m\u001b[0m\u001b[0m\n",
      "\u001b[0;31mTypeError\u001b[0m: object of type 'NoneType' has no len()"
     ]
    }
   ],
   "source": [
    "from flask import Flask, request\n",
    "import socket\n",
    "\n",
    "app = Flask(__name__)\n",
    "\n",
    "# Define the Authoritative Server (AS) address and port\n",
    "AS_IP = '10.9.10.2'\n",
    "AS_PORT = 53533\n",
    "\n",
    "@app.route('/fibonacci')\n",
    "def userServer():\n",
    "    # Check if all required parameters are present in the request\n",
    "    required_params = ['hostname', 'fs_port', 'number', 'as_ip', 'as_port']\n",
    "    for param in required_params:\n",
    "        if param not in request.args:\n",
    "            return 'Missing parameter: ' + param, 400\n",
    "    \n",
    "    # Get the parameters from the request\n",
    "    hostname = request.args['hostname']\n",
    "    fs_port = request.args['fs_port']\n",
    "    number = request.args['number']\n",
    "    as_ip = request.args['as_ip']\n",
    "    as_port = request.args['as_port']\n",
    "    \n",
    "    # Query the Authoritative Server (AS) to get the IP address of the given hostname\n",
    "    s = socket.socket(socket.AF_INET, socket.SOCK_DGRAM)\n",
    "    query = 'TYPE=A\\nNAME=' + hostname + '\\n'\n",
    "    s.sendto(query.encode(), (AS_IP, AS_PORT))\n",
    "    response, _ = s.recvfrom(2048)\n",
    "    response_str = response.decode()\n",
    "    response_lines = response_str.strip().split('\\n')\n",
    "    response_params = {}\n",
    "    for line in response_lines:\n",
    "        key, value = line.split('=')\n",
    "        response_params[key] = value\n",
    "    \n",
    "    # Check if the response from the AS is valid\n",
    "    required_response_params = ['NAME', 'VALUE', 'TYPE']\n",
    "    for param in required_response_params:\n",
    "        if param not in response_params:\n",
    "            return 'Invalid response from AS', 500\n",
    "    \n",
    "    # Get the IP address from the response\n",
    "    fs_ip = response_params['VALUE']\n",
    "    \n",
    "    # Query the Fibonacci Server (FS) to get the Fibonacci number for the given sequence number\n",
    "    fs_url = 'http://' + fs_ip + ':' + fs_port + '/fibonacci?number=' + number\n",
    "    fs_response = requests.get(fs_url)\n",
    "    \n",
    "    # Return the Fibonacci number if the request was successful\n",
    "    if fs_response.status_code == 200:\n",
    "        return fs_response.text, 200\n",
    "    else:\n",
    "        return 'Failed to get Fibonacci number', 500\n",
    "\n",
    "if __name__ == '__main__':\n",
    "    app.run(port=8080)\n"
   ]
  },
  {
   "cell_type": "code",
   "execution_count": null,
   "id": "e0bb7610",
   "metadata": {},
   "outputs": [],
   "source": []
  }
 ],
 "metadata": {
  "kernelspec": {
   "display_name": "Python 3 (ipykernel)",
   "language": "python",
   "name": "python3"
  },
  "language_info": {
   "codemirror_mode": {
    "name": "ipython",
    "version": 3
   },
   "file_extension": ".py",
   "mimetype": "text/x-python",
   "name": "python",
   "nbconvert_exporter": "python",
   "pygments_lexer": "ipython3",
   "version": "3.8.3"
  }
 },
 "nbformat": 4,
 "nbformat_minor": 5
}
